Workbook

Sheet Opsummering
A1: Malingsprodukter – status efter prisjustering 2. september 2026
A2: Shop-priserne er sat efter "DLM fuld prisliste alle produkter" for alle produkter med en direkte linje på listen. Fanen Status viser før/nu pr. produkt, størrelse og farvegruppe.
A4: Status | B4: Antal linjer | C4: Betydning
A5: FØLGER LISTEN | B5: =COUNTIF(Status!$K$2:$K$73,"FØLGER LISTEN") -> 65 | C5: Shop-pris = vejl. udsalgspris
A6: AFVIGER FRA LISTEN | B6: =COUNTIF(Status!$K$2:$K$73,"AFVIGER FRA LISTEN") -> 5 | C6: Har en linje på listen, men prisen er ikke sat (se Note)
A7: INGEN LINJE PÅ LISTEN | B7: =COUNTIF(Status!$K$2:$K$73,"INGEN LINJE PÅ LISTEN") -> 2 | C7: Størrelsen findes ikke på prislisten – ikke ændret
A8: 0 KR I SHOPPEN | B8: =COUNTIF(Status!$K$2:$K$73,"0 KR I SHOPPEN") -> 0 | C8: Kan stadig lægges i kurven gratis
A10: Median-avance nu (linjer med intern pris) | B10: =MEDIAN(Status!H2:H73) -> 0.59763948
A11: Median-prisændring | B11: =MEDIAN(Status!F2:F73) -> 1.010101
A13: Udestående
A14: Træbeskyttelse Glans 20 i 1 L (119) og 3 L (239): ingen linje på listen – står nu meget lavt mod 5 L (749/899).
A15: Tag & sokkelmaling 2,5 L (219) og Transparent træbeskyttelse 5 L ×2 (438): listen har andre størrelser.
A16: 0 kr i shoppen: Loft- & vægmaling Glans 5 (3/5/10 L), Sandspartel Fin/Medium, Letspartel, Vådrumsspartel, Glasfilt, Glasvæv, Mag+, Rutex, Vævlim – ikke på listen, mangler pris.
A17: Produkter uden linje på listen (fanen Kun i shoppen): Vandskuringsmaling, Akryl emalie, Træolie 40, Ædeltræsolie, Universal heldækkende, Tagflex, Microdispersgrunder tixotropisk, Grundingsolie industri.
A18: Produkter på listen som shoppen ikke sælger (fanen Kun på prislisten): Yacht/Model/Festivals Lak, Beton Forsegler, 2K-serien, Anti Grafitti, WWP whiteboard, Vitrulan glasfilt m.fl.
A19: Tema: configurator-variant-map.json genopbygget og "Populær maling"-kortene har fået fast pris – skal pushes for at slå igennem på forsiden.

Sheet Status
A1: Produkt (shop) | B1: Størrelse | C1: Farvegruppe | D1: Pris før | E1: Pris nu | F1: Ændring | G1: Intern pris (kost) | H1: Avance nu | I1: Vejl. pris (prisliste) | J1: Prisliste-linje | K1: Status | L1: Note
A2: Vægmaling Glans 5 | B2: 1L | C2: Råhvid | D2: 99 | E2: 199 | F2: =IF(OR(D2="",E2="",D2=0),"",E2/D2-1) -> 1.010101 | G2: 75 | H2: =IF(OR(G2="",E2=0),"",(E2/(1+Forudsætninger!$B$3)-G2)/(E2/(1+Forudsætninger!$B$3))) -> 0.52889447 | I2: 199 | J2: VÆG GLANS 5 LYS RÅHVID 1 L | K2: =IF(E2=0,"0 KR I SHOPPEN",IF(I2="","INGEN LINJE PÅ LISTEN",IF(E2=I2,"FØLGER LISTEN","AFVIGER FRA LISTEN"))) -> FØLGER LISTEN | L2: Ændret 2. sep 2026 til prislistens pris. Shoppen har én pris for alle 217 farver. Prislisten skelner mellem Lys Råhvid og Base C (tonede farver).
A3: Vægmaling Glans 5 | B3: 1L | C3: Tonede farver (216) | D3: 99 | E3: 229 | F3: =IF(OR(D3="",E3="",D3=0),"",E3/D3-1) -> 1.3131313 | H3: =IF(OR(G3="",E3=0),"",(E3/(1+Forudsætninger!$B$3)-G3)/(E3/(1+Forudsætninger!$B$3))) | I3: 229 | J3: VÆG GLANS 5 BASE C 0,8 L | K3: =IF(E3=0,"0 KR I SHOPPEN",IF(I3="","INGEN LINJE PÅ LISTEN",IF(E3=I3,"FØLGER LISTEN","AFVIGER FRA LISTEN"))) -> FØLGER LISTEN | L3: Ændret 2. sep 2026 til prislistens pris.
A4: Vægmaling Glans 5 | B4: 3L | C4: Råhvid | D4: 199 | E4: 399 | F4: =IF(OR(D4="",E4="",D4=0),"",E4/D4-1) -> 1.0050251 | G4: 165 | H4: =IF(OR(G4="",E4=0),"",(E4/(1+Forudsætninger!$B$3)-G4)/(E4/(1+Forudsætninger!$B$3))) -> 0.48308271 | I4: 399 | J4: VÆG GLANS 5 LYS RÅHVID 3 L | K4: =IF(E4=0,"0 KR I SHOPPEN",IF(I4="","INGEN LINJE PÅ LISTEN",IF(E4=I4,"FØLGER LISTEN","AFVIGER FRA LISTEN"))) -> FØLGER LISTEN | L4: Ændret 2. sep 2026 til prislistens pris.
A5: Vægmaling Glans 5 | B5: 3L | C5: Tonede farver (216) | D5: 199 | E5: 449 | F5: =IF(OR(D5="",E5="",D5=0),"",E5/D5-1) -> 1.2562814 | H5: =IF(OR(G5="",E5=0),"",(E5/(1+Forudsætninger!$B$3)-G5)/(E5/(1+Forudsætninger!$B$3))) | I5: 449 | J5: VÆG GLANS 5 BASE C 2,6 L | K5: =IF(E5=0,"0 KR I SHOPPEN",IF(I5="","INGEN LINJE PÅ LISTEN",IF(E5=I5,"FØLGER LISTEN","AFVIGER FRA LISTEN"))) -> FØLGER LISTEN | L5: Ændret 2. sep 2026 til prislistens pris.
A6: Vægmaling Glans 5 | B6: 5L | C6: Råhvid | D6: 299 | E6: 699 | F6: =IF(OR(D6="",E6="",D6=0),"",E6/D6-1) -> 1.3377926 | G6: 225 | H6: =IF(OR(G6="",E6=0),"",(E6/(1+Forudsætninger!$B$3)-G6)/(E6/(1+Forudsætninger!$B$3))) -> 0.59763948 | I6: 699 | J6: VÆG GLANS 5 LYS RÅHVID 5 L | K6: =IF(E6=0,"0 KR I SHOPPEN",IF(I6="","INGEN LINJE PÅ LISTEN",IF(E6=I6,"FØLGER LISTEN","AFVIGER FRA LISTEN"))) -> FØLGER LISTEN | L6: Ændret 2. sep 2026 til prislistens pris.
A7: Vægmaling Glans 5 | B7: 5L | C7: Tonede farver (216) | D7: 299 | E7: 699 | F7: =IF(OR(D7="",E7="",D7=0),"",E7/D7-1) -> 1.3377926 | H7: =IF(OR(G7="",E7=0),"",(E7/(1+Forudsætninger!$B$3)-G7)/(E7/(1+Forudsætninger!$B$3))) | I7: 699 | J7: VÆG GLANS 5 BASE C 4,8 L | K7: =IF(E7=0,"0 KR I SHOPPEN",IF(I7="","INGEN LINJE PÅ LISTEN",IF(E7=I7,"FØLGER LISTEN","AFVIGER FRA LISTEN"))) -> FØLGER LISTEN | L7: Ændret 2. sep 2026 til prislistens pris.
A8: Vægmaling Glans 5 | B8: 10L | C8: Råhvid | D8: 499 | E8: 1099 | F8: =IF(OR(D8="",E8="",D8=0),"",E8/D8-1) -> 1.2024048 | G8: 250 | H8: =IF(OR(G8="",E8=0),"",(E8/(1+Forudsætninger!$B$3)-G8)/(E8/(1+Forudsætninger!$B$3))) -> 0.71565059 | I8: 1099 | J8: VÆG GLANS 5 LYS RÅHVID 10 L | K8: =IF(E8=0,"0 KR I SHOPPEN",IF(I8="","INGEN LINJE PÅ LISTEN",IF(E8=I8,"FØLGER LISTEN","AFVIGER FRA LISTEN"))) -> FØLGER LISTEN | L8: Ændret 2. sep 2026 til prislistens pris.
A9: Vægmaling Glans 5 | B9: 10L | C9: Tonede farver (216) | D9: 499 | E9: 1199 | F9: =IF(OR(D9="",E9="",D9=0),"",E9/D9-1) -> 1.4028056 | H9: =IF(OR(G9="",E9=0),"",(E9/(1+Forudsætninger!$B$3)-G9)/(E9/(1+Forudsætninger!$B$3))) | I9: 1199 | J9: VÆG GLANS 5 BASE C 9,7 L | K9: =IF(E9=0,"0 KR I SHOPPEN",IF(I9="","INGEN LINJE PÅ LISTEN",IF(E9=I9,"FØLGER LISTEN","AFVIGER FRA LISTEN"))) -> FØLGER LISTEN | L9: Ændret 2. sep 2026 til prislistens pris.
A10: Vægmaling Glans 10 | B10: 1L | C10: Råhvid | D10: 99 | E10: 229 | F10: =IF(OR(D10="",E10="",D10=0),"",E10/D10-1) -> 1.3131313 | G10: 100 | H10: =IF(OR(G10="",E10=0),"",(E10/(1+Forudsætninger!$B$3)-G10)/(E10/(1+Forudsætninger!$B$3))) -> 0.45414847 | I10: 229 | J10: VÆG GLANS 10 LYS RÅHVID 1 L | K10: =IF(E10=0,"0 KR I SHOPPEN",IF(I10="","INGEN LINJE PÅ LISTEN",IF(E10=I10,"FØLGER LISTEN","AFVIGER FRA LISTEN"))) -> FØLGER LISTEN | L10: Ændret 2. sep 2026 til prislistens pris. Som Glans 5.
A11: Vægmaling Glans 10 | B11: 1L | C11: Tonede farver (216) | D11: 99 | E11: 249 | F11: =IF(OR(D11="",E11="",D11=0),"",E11/D11-1) -> 1.5151515 | H11: =IF(OR(G11="",E11=0),"",(E11/(1+Forudsætninger!$B$3)-G11)/(E11/(1+Forudsætninger!$B$3))) | I11: 249 | J11: VÆG GLANS 10 BASE C 0,8 L | K11: =IF(E11=0,"0 KR I SHOPPEN",IF(I11="","INGEN LINJE PÅ LISTEN",IF(E11=I11,"FØLGER LISTEN","AFVIGER FRA LISTEN"))) -> FØLGER LISTEN | L11: Ændret 2. sep 2026 til prislistens pris.
A12: Vægmaling Glans 10 | B12: 3L | C12: Råhvid | D12: 299 | E12: 529 | F12: =IF(OR(D12="",E12="",D12=0),"",E12/D12-1) -> 0.76923077 | G12: 175 | H12: =IF(OR(G12="",E12=0),"",(E12/(1+Forudsætninger!$B$3)-G12)/(E12/(1+Forudsætninger!$B$3))) -> 0.58648393 | I12: 529 | J12: VÆG GLANS 10 LYS RÅHVID 3 L | K12: =IF(E12=0,"0 KR I SHOPPEN",IF(I12="","INGEN LINJE PÅ LISTEN",IF(E12=I12,"FØLGER LISTEN","AFVIGER FRA LISTEN"))) -> FØLGER LISTEN | L12: Ændret 2. sep 2026 til prislistens pris.
A13: Vægmaling Glans 10 | B13: 3L | C13: Tonede farver (216) | D13: 299 | E13: 529 | F13: =IF(OR(D13="",E13="",D13=0),"",E13/D13-1) -> 0.76923077 | H13: =IF(OR(G13="",E13=0),"",(E13/(1+Forudsætninger!$B$3)-G13)/(E13/(1+Forudsætninger!$B$3))) | I13: 529 | J13: VÆG GLANS 10 BASE C 2,6 L | K13: =IF(E13=0,"0 KR I SHOPPEN",IF(I13="","INGEN LINJE PÅ LISTEN",IF(E13=I13,"FØLGER LISTEN","AFVIGER FRA LISTEN"))) -> FØLGER LISTEN | L13: Ændret 2. sep 2026 til prislistens pris.
A14: Vægmaling Glans 10 | B14: 5L | C14: Råhvid | D14: 399 | E14: 749 | F14: =IF(OR(D14="",E14="",D14=0),"",E14/D14-1) -> 0.87719298 | G14: 275 | H14: =IF(OR(G14="",E14=0),"",(E14/(1+Forudsætninger!$B$3)-G14)/(E14/(1+Forudsætninger!$B$3))) -> 0.54105474 | I14: 749 | J14: VÆG GLANS 10 LYS RÅHVID 5 L | K14: =IF(E14=0,"0 KR I SHOPPEN",IF(I14="","INGEN LINJE PÅ LISTEN",IF(E14=I14,"FØLGER LISTEN","AFVIGER FRA LISTEN"))) -> FØLGER LISTEN | L14: Ændret 2. sep 2026 til prislistens pris.
A15: Vægmaling Glans 10 | B15: 5L | C15: Tonede farver (216) | D15: 399 | E15: 849 | F15: =IF(OR(D15="",E15="",D15=0),"",E15/D15-1) -> 1.1278195 | H15: =IF(OR(G15="",E15=0),"",(E15/(1+Forudsætninger!$B$3)-G15)/(E15/(1+Forudsætninger!$B$3))) | I15: 849 | J15: VÆG GLANS 10 BASE C 4,8 L | K15: =IF(E15=0,"0 KR I SHOPPEN",IF(I15="","INGEN LINJE PÅ LISTEN",IF(E15=I15,"FØLGER LISTEN","AFVIGER FRA LISTEN"))) -> FØLGER LISTEN | L15: Ændret 2. sep 2026 til prislistens pris.
A16: Vægmaling Glans 10 | B16: 10L | C16: Råhvid | D16: 499 | E16: 1249 | F16: =IF(OR(D16="",E16="",D16=0),"",E16/D16-1) -> 1.503006 | G16: 300 | H16: =IF(OR(G16="",E16=0),"",(E16/(1+Forudsætninger!$B$3)-G16)/(E16/(1+Forudsætninger!$B$3))) -> 0.69975981 | I16: 1249 | J16: VÆG GLANS 10 LYS RÅHVID 10 L | K16: =IF(E16=0,"0 KR I SHOPPEN",IF(I16="","INGEN LINJE PÅ LISTEN",IF(E16=I16,"FØLGER LISTEN","AFVIGER FRA LISTEN"))) -> FØLGER LISTEN | L16: Ændret 2. sep 2026 til prislistens pris.
A17: Vægmaling Glans 10 | B17: 10L | C17: Tonede farver (216) | D17: 499 | E17: 1349 | F17: =IF(OR(D17="",E17="",D17=0),"",E17/D17-1) -> 1.7034068 | H17: =IF(OR(G17="",E17=0),"",(E17/(1+Forudsætninger!$B$3)-G17)/(E17/(1+Forudsætninger!$B$3))) | I17: 1349 | J17: VÆG GLANS 10 BASE C 9,7 L | K17: =IF(E17=0,"0 KR I SHOPPEN",IF(I17="","INGEN LINJE PÅ LISTEN",IF(E17=I17,"FØLGER LISTEN","AFVIGER FRA LISTEN"))) -> FØLGER LISTEN | L17: Ændret 2. sep 2026 til prislistens pris.
A18: Loftmaling Glans 1 | B18: 1L | C18: Råhvid | D18: 89 | E18: 189 | F18: =IF(OR(D18="",E18="",D18=0),"",E18/D18-1) -> 1.1235955 | G18: 75 | H18: =IF(OR(G18="",E18=0),"",(E18/(1+Forudsætninger!$B$3)-G18)/(E18/(1+Forudsætninger!$B$3))) -> 0.50396825 | I18: 189 | J18: LOFT GLANS 1 LYS RÅHVID 1 L | K18: =IF(E18=0,"0 KR I SHOPPEN",IF(I18="","INGEN LINJE PÅ LISTEN",IF(E18=I18,"FØLGER LISTEN","AFVIGER FRA LISTEN"))) -> FØLGER LISTEN | L18: Ændret 2. sep 2026 til prislistens pris. Prislisten har kun Lys Råhvid for loft – ingen Base C.
A19: Loftmaling Glans 1 | B19: 1L | C19: Tonede farver (216) | D19: 89 | E19: 189 | F19: =IF(OR(D19="",E19="",D19=0),"",E19/D19-1) -> 1.1235955 | G19: 75 | H19: =IF(OR(G19="",E19=0),"",(E19/(1+Forudsætninger!$B$3)-G19)/(E19/(1+Forudsætninger!$B$3))) -> 0.50396825 | I19: 189 | J19: LOFT GLANS 1 LYS RÅHVID 1 L | K19: =IF(E19=0,"0 KR I SHOPPEN",IF(I19="","INGEN LINJE PÅ LISTEN",IF(E19=I19,"FØLGER LISTEN","AFVIGER FRA LISTEN"))) -> FØLGER LISTEN | L19: Ændret 2. sep 2026 til prislistens pris.
A20: Loftmaling Glans 1 | B20: 3L | C20: Råhvid | D20: 179 | E20: 329 | F20: =IF(OR(D20="",E20="",D20=0),"",E20/D20-1) -> 0.83798883 | G20: 165 | H20: =IF(OR(G20="",E20=0),"",(E20/(1+Forudsætninger!$B$3)-G20)/(E20/(1+Forudsætninger!$B$3))) -> 0.3731003 | I20: 329 | J20: LOFT GLANS 1 LYS RÅHVID 3 L | K20: =IF(E20=0,"0 KR I SHOPPEN",IF(I20="","INGEN LINJE PÅ LISTEN",IF(E20=I20,"FØLGER LISTEN","AFVIGER FRA LISTEN"))) -> FØLGER LISTEN | L20: Ændret 2. sep 2026 til prislistens pris.
A21: Loftmaling Glans 1 | B21: 3L | C21: Tonede farver (216) | D21: 179 | E21: 329 | F21: =IF(OR(D21="",E21="",D21=0),"",E21/D21-1) -> 0.83798883 | G21: 165 | H21: =IF(OR(G21="",E21=0),"",(E21/(1+Forudsætninger!$B$3)-G21)/(E21/(1+Forudsætninger!$B$3))) -> 0.3731003 | I21: 329 | J21: LOFT GLANS 1 LYS RÅHVID 3 L | K21: =IF(E21=0,"0 KR I SHOPPEN",IF(I21="","INGEN LINJE PÅ LISTEN",IF(E21=I21,"FØLGER LISTEN","AFVIGER FRA LISTEN"))) -> FØLGER LISTEN | L21: Ændret 2. sep 2026 til prislistens pris.
A22: Loftmaling Glans 1 | B22: 5L | C22: Råhvid | D22: 279 | E22: 599 | F22: =IF(OR(D22="",E22="",D22=0),"",E22/D22-1) -> 1.1469534 | G22: 225 | H22: =IF(OR(G22="",E22=0),"",(E22/(1+Forudsætninger!$B$3)-G22)/(E22/(1+Forudsætninger!$B$3))) -> 0.53046745 | I22: 599 | J22: LOFT GLANS 1 LYS RÅHVID 5 L | K22: =IF(E22=0,"0 KR I SHOPPEN",IF(I22="","INGEN LINJE PÅ LISTEN",IF(E22=I22,"FØLGER LISTEN","AFVIGER FRA LISTEN"))) -> FØLGER LISTEN | L22: Ændret 2. sep 2026 til prislistens pris.
A23: Loftmaling Glans 1 | B23: 5L | C23: Tonede farver (216) | D23: 279 | E23: 599 | F23: =IF(OR(D23="",E23="",D23=0),"",E23/D23-1) -> 1.1469534 | G23: 225 | H23: =IF(OR(G23="",E23=0),"",(E23/(1+Forudsætninger!$B$3)-G23)/(E23/(1+Forudsætninger!$B$3))) -> 0.53046745 | I23: 599 | J23: LOFT GLANS 1 LYS RÅHVID 5 L | K23: =IF(E23=0,"0 KR I SHOPPEN",IF(I23="","INGEN LINJE PÅ LISTEN",IF(E23=I23,"FØLGER LISTEN","AFVIGER FRA LISTEN"))) -> FØLGER LISTEN | L23: Ændret 2. sep 2026 til prislistens pris.
A24: Loftmaling Glans 1 | B24: 10L | C24: Råhvid | D24: 469 | E24: 999 | F24: =IF(OR(D24="",E24="",D24=0),"",E24/D24-1) -> 1.130064 | G24: 250 | H24: =IF(OR(G24="",E24=0),"",(E24/(1+Forudsætninger!$B$3)-G24)/(E24/(1+Forudsætninger!$B$3))) -> 0.68718719 | I24: 999 | J24: LOFT GLANS 1 LYS RÅHVID 10 L | K24: =IF(E24=0,"0 KR I SHOPPEN",IF(I24="","INGEN LINJE PÅ LISTEN",IF(E24=I24,"FØLGER LISTEN","AFVIGER FRA LISTEN"))) -> FØLGER LISTEN | L24: Ændret 2. sep 2026 til prislistens pris.
A25: Loftmaling Glans 1 | B25: 10L | C25: Tonede farver (216) | D25: 469 | E25: 999 | F25: =IF(OR(D25="",E25="",D25=0),"",E25/D25-1) -> 1.130064 | G25: 250 | H25: =IF(OR(G25="",E25=0),"",(E25/(1+Forudsætninger!$B$3)-G25)/(E25/(1+Forudsætninger!$B$3))) -> 0.68718719 | I25: 999 | J25: LOFT GLANS 1 LYS RÅHVID 10 L | K25: =IF(E25=0,"0 KR I SHOPPEN",IF(I25="","INGEN LINJE PÅ LISTEN",IF(E25=I25,"FØLGER LISTEN","AFVIGER FRA LISTEN"))) -> FØLGER LISTEN | L25: Ændret 2. sep 2026 til prislistens pris.
A26: Loftmaling Glans 1 | B26: 12L | C26: Råhvid | D26: 549 | E26: 1149 | F26: =IF(OR(D26="",E26="",D26=0),"",E26/D26-1) -> 1.0928962 | G26: 300 | H26: =IF(OR(G26="",E26=0),"",(E26/(1+Forudsætninger!$B$3)-G26)/(E26/(1+Forudsætninger!$B$3))) -> 0.67362924 | I26: 1149 | J26: LOFT GLANS 1 LYS RÅHVID 12 L | K26: =IF(E26=0,"0 KR I SHOPPEN",IF(I26="","INGEN LINJE PÅ LISTEN",IF(E26=I26,"FØLGER LISTEN","AFVIGER FRA LISTEN"))) -> FØLGER LISTEN | L26: Ændret 2. sep 2026 til prislistens pris.
A27: Loftmaling Glans 5 | B27: 1L | C27: Råhvid | D27: 89 | E27: 189 | F27: =IF(OR(D27="",E27="",D27=0),"",E27/D27-1) -> 1.1235955 | G27: 75 | H27: =IF(OR(G27="",E27=0),"",(E27/(1+Forudsætninger!$B$3)-G27)/(E27/(1+Forudsætninger!$B$3))) -> 0.50396825 | I27: 189 | J27: LOFT GLANS 1 LYS RÅHVID 1 L | K27: =IF(E27=0,"0 KR I SHOPPEN",IF(I27="","INGEN LINJE PÅ LISTEN",IF(E27=I27,"FØLGER LISTEN","AFVIGER FRA LISTEN"))) -> FØLGER LISTEN | L27: Ændret 2. sep 2026 til prislistens pris. Loft Glans 5 findes IKKE på prislisten – sammenlignet med Loft Glans 1 som nærmeste.
A28: Loftmaling Glans 5 | B28: 1L | C28: Tonede farver (216) | D28: 89 | E28: 189 | F28: =IF(OR(D28="",E28="",D28=0),"",E28/D28-1) -> 1.1235955 | G28: 75 | H28: =IF(OR(G28="",E28=0),"",(E28/(1+Forudsætninger!$B$3)-G28)/(E28/(1+Forudsætninger!$B$3))) -> 0.50396825 | I28: 189 | J28: LOFT GLANS 1 LYS RÅHVID 1 L | K28: =IF(E28=0,"0 KR I SHOPPEN",IF(I28="","INGEN LINJE PÅ LISTEN",IF(E28=I28,"FØLGER LISTEN","AFVIGER FRA LISTEN"))) -> FØLGER LISTEN | L28: Ændret 2. sep 2026 til prislistens pris.
A29: Loftmaling Glans 5 | B29: 3L | C29: Råhvid | D29: 179 | E29: 329 | F29: =IF(OR(D29="",E29="",D29=0),"",E29/D29-1) -> 0.83798883 | G29: 165 | H29: =IF(OR(G29="",E29=0),"",(E29/(1+Forudsætninger!$B$3)-G29)/(E29/(1+Forudsætninger!$B$3))) -> 0.3731003 | I29: 329 | J29: LOFT GLANS 1 LYS RÅHVID 3 L | K29: =IF(E29=0,"0 KR I SHOPPEN",IF(I29="","INGEN LINJE PÅ LISTEN",IF(E29=I29,"FØLGER LISTEN","AFVIGER FRA LISTEN"))) -> FØLGER LISTEN | L29: Ændret 2. sep 2026 til prislistens pris.
... A36: Træ & Metal Glans 40 | B36: 1L | C36: Råhvid | D36: 109 | E36: 299 | F36: =IF(OR(D36="",E36="",D36=0),"",E36/D36-1) -> 1.7431193 | G36: 150 | H36: =IF(OR(G36="",E36=0),"",(E36/(1+Forudsætninger!$B$3)-G36)/(E36/(1+Forudsætninger!$B$3))) -> 0.3729097 | I36: 299 | J36: TRÆ & METAL GLANS 40 LYS RÅHVID 1 L | K36: =IF(E36=0,"0 KR I SHOPPEN",IF(I36="","INGEN LINJE PÅ LISTEN",IF(E36=I36,"FØLGER LISTEN","AFVIGER FRA LISTEN"))) -> FØLGER LISTEN | L36: Ændret 2. sep 2026 til prislistens pris.
A37: Træ & Metal Glans 40 | B37: 1L | C37: Tonede farver (216) | D37: 109 | E37: 349 | F37: =IF(OR(D37="",E37="",D37=0),"",E37/D37-1) -> 2.2018349 | H37: =IF(OR(G37="",E37=0),"",(E37/(1+Forudsætninger!$B$3)-G37)/(E37/(1+Forudsætninger!$B$3))) | I37: 349 | J37: TRÆ & METAL GLANS 40 BASE C 0,8 L | K37: =IF(E37=0,"0 KR I SHOPPEN",IF(I37="","INGEN LINJE PÅ LISTEN",IF(E37=I37,"FØLGER LISTEN","AFVIGER FRA LISTEN"))) -> FØLGER LISTEN | L37: Ændret 2. sep 2026 til prislistens pris.
A38: Træ & Metal Glans 40 | B38: 3L | C38: Råhvid | D38: 219 | E38: 649 | F38: =IF(OR(D38="",E38="",D38=0),"",E38/D38-1) -> 1.9634703 | G38: 250 | H38: =IF(OR(G38="",E38=0),"",(E38/(1+Forudsætninger!$B$3)-G38)/(E38/(1+Forudsætninger!$B$3))) -> 0.51848998 | I38: 649 | J38: TRÆ & METAL GLANS 40 LYS RÅHVID 3 L | K38: =IF(E38=0,"0 KR I SHOPPEN",IF(I38="","INGEN LINJE PÅ LISTEN",IF(E38=I38,"FØLGER LISTEN","AFVIGER FRA LISTEN"))) -> FØLGER LISTEN | L38: Ændret 2. sep 2026 til prislistens pris.
A39: Træ & Metal Glans 40 | B39: 3L | C39: Tonede farver (216) | D39: 219 | E39: 699 | F39: =IF(OR(D39="",E39="",D39=0),"",E39/D39-1) -> 2.1917808 | H39: =IF(OR(G39="",E39=0),"",(E39/(1+Forudsætninger!$B$3)-G39)/(E39/(1+Forudsætninger!$B$3))) | I39: 699 | J39: TRÆ & METAL GLANS 40 BASE C 2,7 L | K39: =IF(E39=0,"0 KR I SHOPPEN",IF(I39="","INGEN LINJE PÅ LISTEN",IF(E39=I39,"FØLGER LISTEN","AFVIGER FRA LISTEN"))) -> FØLGER LISTEN | L39: Ændret 2. sep 2026 til prislistens pris.
A40: Træbeskyttelse Glans 20 (farvet) | B40: 1L | C40: Råhvid | D40: 119 | E40: 119 | F40: =IF(OR(D40="",E40="",D40=0),"",E40/D40-1) -> 0 | H40: =IF(OR(G40="",E40=0),"",(E40/(1+Forudsætninger!$B$3)-G40)/(E40/(1+Forudsætninger!$B$3))) | K40: =IF(E40=0,"0 KR I SHOPPEN",IF(I40="","INGEN LINJE PÅ LISTEN",IF(E40=I40,"FØLGER LISTEN","AFVIGER FRA LISTEN"))) -> INGEN LINJE PÅ LISTEN | L40: Ingen tilsvarende størrelse på prislisten – pris IKKE ændret. Står nu meget lavt i forhold til 5 L.
A41: Træbeskyttelse Glans 20 (farvet) | B41: 1L | C41: Tonede farver (216) | D41: 119 | E41: 119 | F41: =IF(OR(D41="",E41="",D41=0),"",E41/D41-1) -> 0 | H41: =IF(OR(G41="",E41=0),"",(E41/(1+Forudsætninger!$B$3)-G41)/(E41/(1+Forudsætninger!$B$3))) | K41: =IF(E41=0,"0 KR I SHOPPEN",IF(I41="","INGEN LINJE PÅ LISTEN",IF(E41=I41,"FØLGER LISTEN","AFVIGER FRA LISTEN"))) -> INGEN LINJE PÅ LISTEN | L41: Ingen tilsvarende størrelse på prislisten – pris IKKE ændret. Står nu meget lavt i forhold til 5 L.
A42: Træbeskyttelse Glans 20 (farvet) | B42: 3L | C42: Råhvid | D42: 239 | E42: 239 | F42: =IF(OR(D42="",E42="",D42=0),"",E42/D42-1) -> 0 | H42: =IF(OR(G42="",E42=0),"",(E42/(1+Forudsætninger!$B$3)-G42)/(E42/(1+Forudsætninger!$B$3))) | I42: 699 | J42: TRÆBESKYTTELSE HELDÆKKENDE OLIEBASERET BASE A 2,5 L | K42: =IF(E42=0,"0 KR I SHOPPEN",IF(I42="","INGEN LINJE PÅ LISTEN",IF(E42=I42,"FØLGER LISTEN","AFVIGER FRA LISTEN"))) -> AFVIGER FRA LISTEN | L42: Ingen tilsvarende størrelse på prislisten – pris IKKE ændret. Står nu meget lavt i forhold til 5 L.
A43: Træbeskyttelse Glans 20 (farvet) | B43: 3L | C43: Tonede farver (216) | D43: 239 | E43: 239 | F43: =IF(OR(D43="",E43="",D43=0),"",E43/D43-1) -> 0 | H43: =IF(OR(G43="",E43=0),"",(E43/(1+Forudsætninger!$B$3)-G43)/(E43/(1+Forudsætninger!$B$3))) | I43: 899 | J43: TRÆBESKYTTELSE HELDÆKKENDE OLIEBASERET BASE C 5 L | K43: =IF(E43=0,"0 KR I SHOPPEN",IF(I43="","INGEN LINJE PÅ LISTEN",IF(E43=I43,"FØLGER LISTEN","AFVIGER FRA LISTEN"))) -> AFVIGER FRA LISTEN | L43: Ingen tilsvarende størrelse på prislisten – pris IKKE ændret. Står nu meget lavt i forhold til 5 L.
A44: Træbeskyttelse Glans 20 (farvet) | B44: 5L | C44: Råhvid | D44: 359 | E44: 749 | F44: =IF(OR(D44="",E44="",D44=0),"",E44/D44-1) -> 1.086351 | G44: 250 | H44: =IF(OR(G44="",E44=0),"",(E44/(1+Forudsætninger!$B$3)-G44)/(E44/(1+Forudsætninger!$B$3))) -> 0.58277704 | I44: 749 | J44: TRÆBESKYTTELSE HELDÆKKENDE OLIEBASERET BASE A 5 L | K44: =IF(E44=0,"0 KR I SHOPPEN",IF(I44="","INGEN LINJE PÅ LISTEN",IF(E44=I44,"FØLGER LISTEN","AFVIGER FRA LISTEN"))) -> FØLGER LISTEN | L44: Ændret 2. sep 2026 til prislistens pris.
A45: Træbeskyttelse Glans 20 (farvet) | B45: 5L | C45: Tonede farver (216) | D45: 359 | E45: 899 | F45: =IF(OR(D45="",E45="",D45=0),"",E45/D45-1) -> 1.5041783 | G45: 250 | H45: =IF(OR(G45="",E45=0),"",(E45/(1+Forudsætninger!$B$3)-G45)/(E45/(1+Forudsætninger!$B$3))) -> 0.65239155 | I45: 899 | J45: TRÆBESKYTTELSE HELDÆKKENDE OLIEBASERET BASE C 5 L | K45: =IF(E45=0,"0 KR I SHOPPEN",IF(I45="","INGEN LINJE PÅ LISTEN",IF(E45=I45,"FØLGER LISTEN","AFVIGER FRA LISTEN"))) -> FØLGER LISTEN | L45: Ændret 2. sep 2026 til prislistens pris.
A46: Træbeskyttelse Glans 20 (farvet) | B46: 10L | C46: Råhvid | D46: 599 | E46: 1699 | F46: =IF(OR(D46="",E46="",D46=0),"",E46/D46-1) -> 1.836394 | H46: =IF(OR(G46="",E46=0),"",(E46/(1+Forudsætninger!$B$3)-G46)/(E46/(1+Forudsætninger!$B$3))) | I46: 1699 | J46: TRÆBESKYTTELSE HELDÆKKENDE OLIEBASERET BASE C 10 L | K46: =IF(E46=0,"0 KR I SHOPPEN",IF(I46="","INGEN LINJE PÅ LISTEN",IF(E46=I46,"FØLGER LISTEN","AFVIGER FRA LISTEN"))) -> FØLGER LISTEN | L46: Ændret 2. sep 2026 til prislistens pris. Prislisten har kun Base C for 10 L – samme pris for alle farver.
...

Sheet Forudsætninger
A1: Forudsætninger
A3: Moms | B3: 0.25
A4: Kilde, prisliste | B4: DLM_fuld_prisliste_alle_produkter.numbers (kilde til sandhed). "Intern pris" = kost ekskl. moms, "Vejl. udsalgspris" = inkl. moms.
A5: Kilde, shop-priser | B5: Shopify. "Pris før" = morgenen 2. sep 2026, "Pris nu" = efter prisjusteringen samme dag (4.365 varianter, 23 produkter).
A6: Regel, farvede malinger | B6: Råhvid = prislistens "Lys Råhvid"-pris. De øvrige 216 farver = prislistens "Base C"-pris. Hvor listen kun har én linje, gælder den for alle farver.
A7: Størrelser | B7: Prislistens 9,7 / 4,8 / 2,6–2,7 / 0,8 L er behandlet som 10 / 5 / 3 / 1 L. Andre afvigende størrelser er IKKE ændret (se Note).
A8: Avance | B8: (pris ekskl. moms − intern pris) / pris ekskl. moms
A10: Blå celler kan ændres.

Sheet Kun i shoppen
A1: Produkt | B1: Størrelse | C1: Shop-pris | D1: Bemærkning
A2: Loft- & vægmaling Glans 5 | B2: 3 L | C2: 0 | D2: Ingen tilsvarende linje på prislisten – pris ikke ændret – STÅR TIL 0 KR
A3: Loft- & vægmaling Glans 5 | B3: 5 L | C3: 0 | D3: Ingen tilsvarende linje på prislisten – pris ikke ændret – STÅR TIL 0 KR
A4: Loft- & vægmaling Glans 5 | B4: 10 L | C4: 0 | D4: Ingen tilsvarende linje på prislisten – pris ikke ændret – STÅR TIL 0 KR
A5: Vandskuringsmaling | B5: 10 L | C5: 500 | D5: Ingen tilsvarende linje på prislisten – pris ikke ændret
A6: Akryl emalie Glans 40 | B6: 1 L | C6: 225 | D6: Ingen tilsvarende linje på prislisten – pris ikke ændret
A7: Akryl emalie Glans 40 | B7: 3 L | C7: 638 | D7: Ingen tilsvarende linje på prislisten – pris ikke ændret
A8: Transparent træbeskyttelse (tixotropisk) | B8: 5 L | C8: 438 | D8: Ingen tilsvarende linje på prislisten – pris ikke ændret
A9: Træolie 40 (olie-baseret) | B9: 2,5 L | C9: 250 | D9: Ingen tilsvarende linje på prislisten – pris ikke ændret
A10: Træolie 40 (olie-baseret) | B10: 5 L | C10: 438 | D10: Ingen tilsvarende linje på prislisten – pris ikke ændret
A11: Ædeltræsolie (gylden) | B11: 5 L | C11: 563 | D11: Ingen tilsvarende linje på prislisten – pris ikke ændret
A12: Universal heldækkende (olie-baseret) til træ/sten/eternit | B12: 5 L | C12: 563 | D12: Ingen tilsvarende linje på prislisten – pris ikke ændret
A13: Tagflex (gummimaling) | B13: 20 L | C13: 1500 | D13: Ingen tilsvarende linje på prislisten – pris ikke ændret
... A15: Grundingsolie vandig (industri) | B15: 20 L | C15: 750 | D15: Ingen tilsvarende linje på prislisten – pris ikke ændret

Sheet Kun på prislisten
A1: Nr. | B1: Produkt | C1: Størrelse | D1: Intern pris | E1: Vejl. udsalgspris | F1: Bemærkning
A2: 6 | B2: VÆG GLANS 5 LYS RÅHVID | C2: 12 L | D2: 300 | E2: 1299 | F2: Anden størrelse af et produkt shoppen fører
A3: 15 | B3: VÆG GLANS 5 BASE C (Farveprøve) | C3: 0,3 L | D3: 30 | E3: 50 | F3: Produktet findes ikke i shoppen
A4: 27 | B4: KØKKEN & BAD GLANS 25 LYS RÅHVID | C4: 1 L | D4: 110 | E4: 299 | F4: Anden størrelse af et produkt shoppen fører
A5: 31 | B5: KØKKEN & BAD GLANS 25 BASE C | C5: 0,8 L | D5: 125 | E5: 249 | F5: Anden størrelse af et produkt shoppen fører
A6: 37 | B6: MICRODISPERS BLÅ TONET | C6: 5 L | D6: 65 | E6: 249 | F6: Anden størrelse af et produkt shoppen fører
A7: 38 | B7: MICRODISPERS BLÅ TONET | C7: 3 L | D7: 40 | E7: 199 | F7: Anden størrelse af et produkt shoppen fører
A8: 39 | B8: MICRODISPERS BLÅ TONET | C8: 1 L | D8: 30 | E8: 99 | F8: Anden størrelse af et produkt shoppen fører
A9: 41 | B9: MICRODISPERS GRUNDER HVID | C9: 5 L | D9: 120 | E9: 299 | F9: Anden størrelse af et produkt shoppen fører
A10: 42 | B10: MICRODISPERS GRUNDER HVID | C10: 3 L | D10: 85 | E10: 249 | F10: Anden størrelse af et produkt shoppen fører
A11: 43 | B11: MICRODISPERS GRUNDER HVID | C11: 1 L | D11: 65 | E11: 149 | F11: Anden størrelse af et produkt shoppen fører
A12: 48 | B12: TAG & FACADE GLANS 60 BASE C | C12: 10 L | D12: 285 | E12: 1199 | F12: Anden størrelse af et produkt shoppen fører
A13: 52 | B13: FACADE AKRYL / OLIE BASE C | C13: 3 L | D13: 185 | E13: 649 | F13: Anden størrelse af et produkt shoppen fører
A14: 55 | B14: FACADE AKRYL / OLIE BASE A | C14: 3 L | E14: 599 | F14: Anden størrelse af et produkt shoppen fører
A15: 60 | B15: TRÆBESKYTTELSE HELDÆKKENDE VANDIG BASE C | C15: 10 L | D15: 450 | E15: 1699 | F15: Anden størrelse af et produkt shoppen fører
A16: 62 | B16: TRÆBESKYTTELSE HELDÆKKENDE VANDIG BASE A | C16: 10 L | D16: 425 | E16: 1599 | F16: Anden størrelse af et produkt shoppen fører
A17: 68 | B17: TRÆBESKYTTELSE TRANSPARENT OLIEBASERET SORT | C17: 2,5 L | D17: 130 | E17: 699 | F17: Produktet findes ikke i shoppen
A18: 70 | B18: TRÆBESKYTTELSE TRANSPARENT OLIEBASERET PINE | C18: 2,5 L | D18: 130 | E18: 699 | F18: Produktet findes ikke i shoppen
A19: 71 | B19: TRÆBESKYTTELSE TRANSPARENT OLIEBASERET NØD | C19: 2,5 L | D19: 130 | E19: 699 | F19: Produktet findes ikke i shoppen
A20: 72 | B20: TRÆBESKYTTELSE TRANSPARENT OLIEBASERET MAHOGNI | C20: 2,5 L | D20: 130 | E20: 699 | F20: Produktet findes ikke i shoppen
A21: 73 | B21: TRÆBESKYTTELSE TRANSPARENT OLIEBASERET TEAK | C21: 2,5 L | D21: 130 | E21: 699 | F21: Produktet findes ikke i shoppen
A22: 74 | B22: TRÆBESKYTTELSE TRANSPARENT OLIEBASERET IMPR. GRØN | C22: 2,5 L | D22: 130 | E22: 699 | F22: Produktet findes ikke i shoppen
A23: 76 | B23: UDE RENS 1.10 | C23: 3 L | D23: 30 | E23: 199 | F23: Anden størrelse af et produkt shoppen fører
A24: 77 | B24: UDE RENS 1.10 | C24: 1 L | D24: 30 | E24: 149 | F24: Anden størrelse af et produkt shoppen fører
A25: 78 | B25: SOKKEL MALING GLANS 20 BASE C | C25: 10 L | D25: 300 | E25: 1499 | F25: Anden størrelse af et produkt shoppen fører
A26: 82 | B26: TERRESSEOLIE PINE | C26: 5 L | D26: 130 | E26: 499 | F26: Produktet findes ikke i shoppen
... A74: 131 | B74: LF Beton Forsegler | C74: 200 L | D74: 12000 | E74: 40000 | F74: Produktet findes ikke i shoppen
A75: 132 | B75: LF Container 2K Maling 2 i 1 A + B | C75: 3 KG | D75: 375 + 100 | E75: 1100 | F75: Produktet findes ikke i shoppen
A76: 133 | B76: LF Container 2K Maling 2 i 1 A + B | C76: 5 KG | D76: 625 + 200 | E76: 1800 | F76: Produktet findes ikke i shoppen
A77: 134 | B77: LF Container 2K Maling 2 i 1 A + B | C77: 20 KG | D77: 2000 + 400 | E77: 4400 | F77: Produktet findes ikke i shoppen
A78: 135 | B78: LF Maskine Maling 2K A + B | C78: 3 KG | D78: 375 + 100 | E78: 1100 | F78: Produktet findes ikke i shoppen
A79: 136 | B79: LF Maskine Maling 2K A + B | C79: 5 KG | D79: 625 + 200 | E79: 1800 | F79: Produktet findes ikke i shoppen
A80: 137 | B80: LF Maskine Maling 2K A + B | C80: 20 KG | D80: 2000 + 400 | E80: 4400 | F80: Produktet findes ikke i shoppen
A81: 138 | B81: LF OneCoat 2K A + B | C81: 3 KG | D81: 375 + 100 | E81: 1100 | F81: Produktet findes ikke i shoppen
A82: 139 | B82: LF OneCoat 2K A + B | C82: 5 KG | D82: 625 + 200 | E82: 1800 | F82: Produktet findes ikke i shoppen
A83: 140 | B83: LF OneCoat 2K A + B | C83: 20 KG | D83: 2000 + 400 | E83: 4400 | F83: Produktet findes ikke i shoppen
A84: 141 | B84: LF Anti Grafitti | C84: 2,5 L | D84: 150 | E84: 700 | F84: Produktet findes ikke i shoppen
A85: 142 | B85: LF Anti Grafitti | C85: 5 L | D85: 300 | E85: 1350 | F85: Produktet findes ikke i shoppen
A86: 143 | B86: LF Anti Grafitti | C86: 20 L | D86: 1200 | E86: 5400 | F86: Produktet findes ikke i shoppen
