Workbook

Sheet Opsummering
A1: Prisanalyse – Lars Frey-sortimentet
A2: Shopify-priser pr. 2. sep 2026 (efter dagens hævning af KRITISK-gruppen) mod leverandørens kostpriser. Alle 304 varianter på fanen Prisanalyse; moms og målavance på Forudsætninger.
A4: Prioritet | B4: Antal varianter | C4: Betydning
A5: KRITISK | B5: =COUNTIF(Prisanalyse!$I$2:$I$305,"KRITISK") -> 0 | C5: Sælges under kostpris / 0 kr
A6: HØJ | B6: =COUNTIF(Prisanalyse!$I$2:$I$305,"HØJ") -> 91 | C6: Under 20 % avance – næste runde
A7: MIDDEL | B7: =COUNTIF(Prisanalyse!$I$2:$I$305,"MIDDEL") -> 75 | C7: 20–35 % avance – vurdér produkt for produkt
A8: OK | B8: =COUNTIF(Prisanalyse!$I$2:$I$305,"OK") -> 120 | C8: 35 %+ – lad stå
A9: UKENDT | B9: =COUNTIF(Prisanalyse!$I$2:$I$305,"UKENDT") -> 18 | C9: Ingen kostpris fundet – slå op hos leverandøren
A11: Median-avance i dag (varianter med kostpris) | B11: =MEDIAN(Prisanalyse!H2:H305) -> 0.29836135
A12: Median-avance efter foreslåede priser | B12: =MEDIAN(Prisanalyse!L2:L305) -> 0.45418478
A14: Pr. kategori
A15: Kategori | B15: Varianter | C15: Heraf HØJ | D15: Heraf MIDDEL
A16: Afdækning | B16: =COUNTIF(Prisanalyse!$A$2:$A$305,A16) -> 15 | C16: =COUNTIFS(Prisanalyse!$A$2:$A$305,A16,Prisanalyse!$I$2:$I$305,"HØJ") -> 4 | D16: =COUNTIFS(Prisanalyse!$A$2:$A$305,A16,Prisanalyse!$I$2:$I$305,"MIDDEL") -> 8
A17: Anstrygere | B17: =COUNTIF(Prisanalyse!$A$2:$A$305,A17) -> 3 | C17: =COUNTIFS(Prisanalyse!$A$2:$A$305,A17,Prisanalyse!$I$2:$I$305,"HØJ") -> 1 | D17: =COUNTIFS(Prisanalyse!$A$2:$A$305,A17,Prisanalyse!$I$2:$I$305,"MIDDEL") -> 0
A18: Diverse | B18: =COUNTIF(Prisanalyse!$A$2:$A$305,A18) -> 33 | C18: =COUNTIFS(Prisanalyse!$A$2:$A$305,A18,Prisanalyse!$I$2:$I$305,"HØJ") -> 10 | D18: =COUNTIFS(Prisanalyse!$A$2:$A$305,A18,Prisanalyse!$I$2:$I$305,"MIDDEL") -> 6
A19: Handsker | B19: =COUNTIF(Prisanalyse!$A$2:$A$305,A19) -> 4 | C19: =COUNTIFS(Prisanalyse!$A$2:$A$305,A19,Prisanalyse!$I$2:$I$305,"HØJ") -> 0 | D19: =COUNTIFS(Prisanalyse!$A$2:$A$305,A19,Prisanalyse!$I$2:$I$305,"MIDDEL") -> 4
A20: Malerbakker | B20: =COUNTIF(Prisanalyse!$A$2:$A$305,A20) -> 4 | C20: =COUNTIFS(Prisanalyse!$A$2:$A$305,A20,Prisanalyse!$I$2:$I$305,"HØJ") -> 0 | D20: =COUNTIFS(Prisanalyse!$A$2:$A$305,A20,Prisanalyse!$I$2:$I$305,"MIDDEL") -> 3
A21: Pensler | B21: =COUNTIF(Prisanalyse!$A$2:$A$305,A21) -> 58 | C21: =COUNTIFS(Prisanalyse!$A$2:$A$305,A21,Prisanalyse!$I$2:$I$305,"HØJ") -> 10 | D21: =COUNTIFS(Prisanalyse!$A$2:$A$305,A21,Prisanalyse!$I$2:$I$305,"MIDDEL") -> 18
A22: Rullehåndtag | B22: =COUNTIF(Prisanalyse!$A$2:$A$305,A22) -> 10 | C22: =COUNTIFS(Prisanalyse!$A$2:$A$305,A22,Prisanalyse!$I$2:$I$305,"HØJ") -> 6 | D22: =COUNTIFS(Prisanalyse!$A$2:$A$305,A22,Prisanalyse!$I$2:$I$305,"MIDDEL") -> 0
A23: Ruller | B23: =COUNTIF(Prisanalyse!$A$2:$A$305,A23) -> 27 | C23: =COUNTIFS(Prisanalyse!$A$2:$A$305,A23,Prisanalyse!$I$2:$I$305,"HØJ") -> 7 | D23: =COUNTIFS(Prisanalyse!$A$2:$A$305,A23,Prisanalyse!$I$2:$I$305,"MIDDEL") -> 7
A24: Sandpapir | B24: =COUNTIF(Prisanalyse!$A$2:$A$305,A24) -> 101 | C24: =COUNTIFS(Prisanalyse!$A$2:$A$305,A24,Prisanalyse!$I$2:$I$305,"HØJ") -> 35 | D24: =COUNTIFS(Prisanalyse!$A$2:$A$305,A24,Prisanalyse!$I$2:$I$305,"MIDDEL") -> 20
A25: Spartler | B25: =COUNTIF(Prisanalyse!$A$2:$A$305,A25) -> 10 | C25: =COUNTIFS(Prisanalyse!$A$2:$A$305,A25,Prisanalyse!$I$2:$I$305,"HØJ") -> 1 | D25: =COUNTIFS(Prisanalyse!$A$2:$A$305,A25,Prisanalyse!$I$2:$I$305,"MIDDEL") -> 0
A26: Tape | B26: =COUNTIF(Prisanalyse!$A$2:$A$305,A26) -> 25 | C26: =COUNTIFS(Prisanalyse!$A$2:$A$305,A26,Prisanalyse!$I$2:$I$305,"HØJ") -> 13 | D26: =COUNTIFS(Prisanalyse!$A$2:$A$305,A26,Prisanalyse!$I$2:$I$305,"MIDDEL") -> 7
A27: Tilbehør | B27: =COUNTIF(Prisanalyse!$A$2:$A$305,A27) -> 14 | C27: =COUNTIFS(Prisanalyse!$A$2:$A$305,A27,Prisanalyse!$I$2:$I$305,"HØJ") -> 4 | D27: =COUNTIFS(Prisanalyse!$A$2:$A$305,A27,Prisanalyse!$I$2:$I$305,"MIDDEL") -> 2

Sheet Prisanalyse
A1: Kategori | B1: Produkt | C1: Variant | D1: SKU | E1: Pris i dag (inkl. moms) | F1: Pris ekskl. moms | G1: Kostpris ekskl. moms | H1: Avance i dag | I1: Prioritet | J1: Foreslået pris (inkl. moms) | K1: Stigning | L1: Ny avance | M1: Leverandørens varenavn | N1: Note
A2: Tape | B2: Washi-Tec Sensitive | Tape | C2: 48 mm | D2: 309-48 | E2: 161 | F2: =E2/(1+Forudsætninger!$B$3) -> 128.8 | G2: 128.7 | H2: =IF(OR(G2="",F2=0),"",(F2-G2)/F2) -> 0.00077639752 | I2: =IF(G2="","UKENDT",IF(OR(E2=0,H2<0),"KRITISK",IF(H2<0.2,"HØJ",IF(H2<0.35,"MIDDEL","OK")))) -> HØJ | J2: =IF(G2="","",MAX(E2,CEILING(G2/(1-Forudsætninger!$B$4)*(1+Forudsætninger!$B$3),IF(G2/(1-Forudsætninger!$B$4)*(1+Forudsætninger!$B$3)<50,1,IF(G2/(1-Forudsætninger!$B$4)*(1+Forudsætninger!$B$3)<200,5,10))))) -> 300 | K2: =IF(OR(J2="",E2=0),"",J2/E2-1) -> 0.86335404 | L2: =IF(J2="","",(J2/(1+Forudsætninger!$B$3)-G2)/(J2/(1+Forudsætninger!$B$3))) -> 0.46375 | M2: Kip Washi-Tec Sensitive Malertape 48 mm x 50 meter. 20stk/kolli.
A3: Diverse | B3: Fladpensel | C3: 40 mm | D3: 52-FACILE/40 | E3: 22 | F3: =E3/(1+Forudsætninger!$B$3) -> 17.6 | G3: 17.556 | H3: =IF(OR(G3="",F3=0),"",(F3-G3)/F3) -> 0.0025 | I3: =IF(G3="","UKENDT",IF(OR(E3=0,H3<0),"KRITISK",IF(H3<0.2,"HØJ",IF(H3<0.35,"MIDDEL","OK")))) -> HØJ | J3: =IF(G3="","",MAX(E3,CEILING(G3/(1-Forudsætninger!$B$4)*(1+Forudsætninger!$B$3),IF(G3/(1-Forudsætninger!$B$4)*(1+Forudsætninger!$B$3)<50,1,IF(G3/(1-Forudsætninger!$B$4)*(1+Forudsætninger!$B$3)<200,5,10))))) -> 40 | K3: =IF(OR(J3="",E3=0),"",J3/E3-1) -> 0.81818182 | L3: =IF(J3="","",(J3/(1+Forudsætninger!$B$3)-G3)/(J3/(1+Forudsætninger!$B$3))) -> 0.451375 | M3: Pronelli. Fladpensel 40mm Mix/plastskaft.
A4: Diverse | B4: Fladpensel | C4: 70 mm | D4: 52-FACILE/70 | E4: 40 | F4: =E4/(1+Forudsætninger!$B$3) -> 32 | G4: 31.9 | H4: =IF(OR(G4="",F4=0),"",(F4-G4)/F4) -> 0.003125 | I4: =IF(G4="","UKENDT",IF(OR(E4=0,H4<0),"KRITISK",IF(H4<0.2,"HØJ",IF(H4<0.35,"MIDDEL","OK")))) -> HØJ | J4: =IF(G4="","",MAX(E4,CEILING(G4/(1-Forudsætninger!$B$4)*(1+Forudsætninger!$B$3),IF(G4/(1-Forudsætninger!$B$4)*(1+Forudsætninger!$B$3)<50,1,IF(G4/(1-Forudsætninger!$B$4)*(1+Forudsætninger!$B$3)<200,5,10))))) -> 75 | K4: =IF(OR(J4="",E4=0),"",J4/E4-1) -> 0.875 | L4: =IF(J4="","",(J4/(1+Forudsætninger!$B$3)-G4)/(J4/(1+Forudsætninger!$B$3))) -> 0.46833333 | M4: Pronelli. Fladpensel 70mm Mix/plastskaft.
A5: Anstrygere | B5: Anstryger | Natur | C5: 70x170 mm | D5: 52-254/70170 | E5: 450 | F5: =E5/(1+Forudsætninger!$B$3) -> 360 | G5: 358.468 | H5: =IF(OR(G5="",F5=0),"",(F5-G5)/F5) -> 0.0042555556 | I5: =IF(G5="","UKENDT",IF(OR(E5=0,H5<0),"KRITISK",IF(H5<0.2,"HØJ",IF(H5<0.35,"MIDDEL","OK")))) -> HØJ | J5: =IF(G5="","",MAX(E5,CEILING(G5/(1-Forudsætninger!$B$4)*(1+Forudsætninger!$B$3),IF(G5/(1-Forudsætninger!$B$4)*(1+Forudsætninger!$B$3)<50,1,IF(G5/(1-Forudsætninger!$B$4)*(1+Forudsætninger!$B$3)<200,5,10))))) -> 820 | K5: =IF(OR(J5="",E5=0),"",J5/E5-1) -> 0.82222222 | L5: =IF(J5="","",(J5/(1+Forudsætninger!$B$3)-G5)/(J5/(1+Forudsætninger!$B$3))) -> 0.45355488 | M5: Gamma Anstryger Naturbørste m/Softgrib 70x170mm - 604581
A6: Tape | B6: Ultra Sharp Red | Tape | C6: 24 mm | D6: 3301-24 | E6: 111 | F6: =E6/(1+Forudsætninger!$B$3) -> 88.8 | G6: 88 | H6: =IF(OR(G6="",F6=0),"",(F6-G6)/F6) -> 0.009009009 | I6: =IF(G6="","UKENDT",IF(OR(E6=0,H6<0),"KRITISK",IF(H6<0.2,"HØJ",IF(H6<0.35,"MIDDEL","OK")))) -> HØJ | J6: =IF(G6="","",MAX(E6,CEILING(G6/(1-Forudsætninger!$B$4)*(1+Forudsætninger!$B$3),IF(G6/(1-Forudsætninger!$B$4)*(1+Forudsætninger!$B$3)<50,1,IF(G6/(1-Forudsætninger!$B$4)*(1+Forudsætninger!$B$3)<200,5,10))))) -> 200 | K6: =IF(OR(J6="",E6=0),"",J6/E6-1) -> 0.8018018 | L6: =IF(J6="","",(J6/(1+Forudsætninger!$B$3)-G6)/(J6/(1+Forudsætninger!$B$3))) -> 0.45 | M6: ULTRA SHARP RED 24X50MM 36STK/KOLLI.
A7: Tape | B7: Projekt Washi UV tape | Tape | C7: 48 mm | D7: 508-48 | E7: 90 | F7: =E7/(1+Forudsætninger!$B$3) -> 72 | G7: 70.4 | H7: =IF(OR(G7="",F7=0),"",(F7-G7)/F7) -> 0.022222222 | I7: =IF(G7="","UKENDT",IF(OR(E7=0,H7<0),"KRITISK",IF(H7<0.2,"HØJ",IF(H7<0.35,"MIDDEL","OK")))) -> HØJ | J7: =IF(G7="","",MAX(E7,CEILING(G7/(1-Forudsætninger!$B$4)*(1+Forudsætninger!$B$3),IF(G7/(1-Forudsætninger!$B$4)*(1+Forudsætninger!$B$3)<50,1,IF(G7/(1-Forudsætninger!$B$4)*(1+Forudsætninger!$B$3)<200,5,10))))) -> 160 | K7: =IF(OR(J7="",E7=0),"",J7/E7-1) -> 0.77777778 | L7: =IF(J7="","",(J7/(1+Forudsætninger!$B$3)-G7)/(J7/(1+Forudsætninger!$B$3))) -> 0.45 | M7: Projekt Washi UV TAPE. 48MMX50M 36. 20STK/KOLLI.
A8: Diverse | B8: Fladpensel | C8: 60 mm | D8: 52-FACILE/60 | E8: 34 | F8: =E8/(1+Forudsætninger!$B$3) -> 27.2 | G8: 26.576 | H8: =IF(OR(G8="",F8=0),"",(F8-G8)/F8) -> 0.022941176 | I8: =IF(G8="","UKENDT",IF(OR(E8=0,H8<0),"KRITISK",IF(H8<0.2,"HØJ",IF(H8<0.35,"MIDDEL","OK")))) -> HØJ | J8: =IF(G8="","",MAX(E8,CEILING(G8/(1-Forudsætninger!$B$4)*(1+Forudsætninger!$B$3),IF(G8/(1-Forudsætninger!$B$4)*(1+Forudsætninger!$B$3)<50,1,IF(G8/(1-Forudsætninger!$B$4)*(1+Forudsætninger!$B$3)<200,5,10))))) -> 65 | K8: =IF(OR(J8="",E8=0),"",J8/E8-1) -> 0.91176471 | L8: =IF(J8="","",(J8/(1+Forudsætninger!$B$3)-G8)/(J8/(1+Forudsætninger!$B$3))) -> 0.48892308 | M8: Pronelli. Fladpensel 60mm Mix/plastskaft.
A9: Pensler | B9: Facadepensel | Mix | C9: 120mm | D9: 52-212/312 | E9: 106 | F9: =E9/(1+Forudsætninger!$B$3) -> 84.8 | G9: 82.478 | H9: =IF(OR(G9="",F9=0),"",(F9-G9)/F9) -> 0.027382075 | I9: =IF(G9="","UKENDT",IF(OR(E9=0,H9<0),"KRITISK",IF(H9<0.2,"HØJ",IF(H9<0.35,"MIDDEL","OK")))) -> HØJ | J9: =IF(G9="","",MAX(E9,CEILING(G9/(1-Forudsætninger!$B$4)*(1+Forudsætninger!$B$3),IF(G9/(1-Forudsætninger!$B$4)*(1+Forudsætninger!$B$3)<50,1,IF(G9/(1-Forudsætninger!$B$4)*(1+Forudsætninger!$B$3)<200,5,10))))) -> 190 | K9: =IF(OR(J9="",E9=0),"",J9/E9-1) -> 0.79245283 | L9: =IF(J9="","",(J9/(1+Forudsætninger!$B$3)-G9)/(J9/(1+Forudsætninger!$B$3))) -> 0.45738158 | M9: Gamma Anstryge mix børster 3x312
A10: Tape | B10: Washi Tape Premium | Tape | C10: 24 mm | D10: 3808-24 | E10: 60 | F10: =E10/(1+Forudsætninger!$B$3) -> 48 | G10: 46.64 | H10: =IF(OR(G10="",F10=0),"",(F10-G10)/F10) -> 0.028333333 | I10: =IF(G10="","UKENDT",IF(OR(E10=0,H10<0),"KRITISK",IF(H10<0.2,"HØJ",IF(H10<0.35,"MIDDEL","OK")))) -> HØJ | J10: =IF(G10="","",MAX(E10,CEILING(G10/(1-Forudsætninger!$B$4)*(1+Forudsætninger!$B$3),IF(G10/(1-Forudsætninger!$B$4)*(1+Forudsætninger!$B$3)<50,1,IF(G10/(1-Forudsætninger!$B$4)*(1+Forudsætninger!$B$3)<200,5,10))))) -> 110 | K10: =IF(OR(J10="",E10=0),"",J10/E10-1) -> 0.83333333 | L10: =IF(J10="","",(J10/(1+Forudsætninger!$B$3)-G10)/(J10/(1+Forudsætninger!$B$3))) -> 0.47 | M10: WASHI TAPE PREMIUM 24X50MM 36STK/KOLLI.
A11: Diverse | B11: Fladpensel | C11: 20 mm | D11: 52-FACILE/20 | E11: 18 | F11: =E11/(1+Forudsætninger!$B$3) -> 14.4 | G11: 13.86 | H11: =IF(OR(G11="",F11=0),"",(F11-G11)/F11) -> 0.0375 | I11: =IF(G11="","UKENDT",IF(OR(E11=0,H11<0),"KRITISK",IF(H11<0.2,"HØJ",IF(H11<0.35,"MIDDEL","OK")))) -> HØJ | J11: =IF(G11="","",MAX(E11,CEILING(G11/(1-Forudsætninger!$B$4)*(1+Forudsætninger!$B$3),IF(G11/(1-Forudsætninger!$B$4)*(1+Forudsætninger!$B$3)<50,1,IF(G11/(1-Forudsætninger!$B$4)*(1+Forudsætninger!$B$3)<200,5,10))))) -> 32 | K11: =IF(OR(J11="",E11=0),"",J11/E11-1) -> 0.77777778 | L11: =IF(J11="","",(J11/(1+Forudsætninger!$B$3)-G11)/(J11/(1+Forudsætninger!$B$3))) -> 0.45859375 | M11: Pronelli. Fladpensel 20mm Mix/plastskaft.
A12: Tilbehør | B12: Hobbykniv | C12: 18mm (48 stk.) | D12: 811502K | E12: 16 | F12: =E12/(1+Forudsætninger!$B$3) -> 12.8 | G12: 12.1 | H12: =IF(OR(G12="",F12=0),"",(F12-G12)/F12) -> 0.0546875 | I12: =IF(G12="","UKENDT",IF(OR(E12=0,H12<0),"KRITISK",IF(H12<0.2,"HØJ",IF(H12<0.35,"MIDDEL","OK")))) -> HØJ | J12: =IF(G12="","",MAX(E12,CEILING(G12/(1-Forudsætninger!$B$4)*(1+Forudsætninger!$B$3),IF(G12/(1-Forudsætninger!$B$4)*(1+Forudsætninger!$B$3)<50,1,IF(G12/(1-Forudsætninger!$B$4)*(1+Forudsætninger!$B$3)<200,5,10))))) -> 28 | K12: =IF(OR(J12="",E12=0),"",J12/E12-1) -> 0.75 | L12: =IF(J12="","",(J12/(1+Forudsætninger!$B$3)-G12)/(J12/(1+Forudsætninger!$B$3))) -> 0.45982143 | M12: Cutter Kniv 18mm. MK. 48 stk/pr kasse.
A13: Tilbehør | B13: Hobbykniv | C13: 18mm (6 stk.) | D13: 816920SB | E13: 56 | F13: =E13/(1+Forudsætninger!$B$3) -> 44.8 | G13: 41.8 | H13: =IF(OR(G13="",F13=0),"",(F13-G13)/F13) -> 0.066964286 | I13: =IF(G13="","UKENDT",IF(OR(E13=0,H13<0),"KRITISK",IF(H13<0.2,"HØJ",IF(H13<0.35,"MIDDEL","OK")))) -> HØJ | J13: =IF(G13="","",MAX(E13,CEILING(G13/(1-Forudsætninger!$B$4)*(1+Forudsætninger!$B$3),IF(G13/(1-Forudsætninger!$B$4)*(1+Forudsætninger!$B$3)<50,1,IF(G13/(1-Forudsætninger!$B$4)*(1+Forudsætninger!$B$3)<200,5,10))))) -> 95 | K13: =IF(OR(J13="",E13=0),"",J13/E13-1) -> 0.69642857 | L13: =IF(J13="","",(J13/(1+Forudsætninger!$B$3)-G13)/(J13/(1+Forudsætninger!$B$3))) -> 0.45 | M13: Cutter Kniv Premium 18mm. MK. 6 stk/pr kasse.
... A40: Rullehåndtag | B40: Håndtag 10 cm | Håndtag | C40: 10 cm | D40: 725412SB | E40: 44 | F40: =E40/(1+Forudsætninger!$B$3) -> 35.2 | G40: 31.9 | H40: =IF(OR(G40="",F40=0),"",(F40-G40)/F40) -> 0.09375 | I40: =IF(G40="","UKENDT",IF(OR(E40=0,H40<0),"KRITISK",IF(H40<0.2,"HØJ",IF(H40<0.35,"MIDDEL","OK")))) -> HØJ | J40: =IF(G40="","",MAX(E40,CEILING(G40/(1-Forudsætninger!$B$4)*(1+Forudsætninger!$B$3),IF(G40/(1-Forudsætninger!$B$4)*(1+Forudsætninger!$B$3)<50,1,IF(G40/(1-Forudsætninger!$B$4)*(1+Forudsætninger!$B$3)<200,5,10))))) -> 75 | K40: =IF(OR(J40="",E40=0),"",J40/E40-1) -> 0.70454545 | L40: =IF(J40="","",(J40/(1+Forudsætninger!$B$3)-G40)/(J40/(1+Forudsætninger!$B$3))) -> 0.46833333 | M40: Håndtag 10cm. Soft Grib. MK
A41: Sandpapir | B41: Slibeklods, kork | Slibepapir | C41: 70x93 mm | D41: 85912 | E41: 44 | F41: =E41/(1+Forudsætninger!$B$3) -> 35.2 | G41: 31.9 | H41: =IF(OR(G41="",F41=0),"",(F41-G41)/F41) -> 0.09375 | I41: =IF(G41="","UKENDT",IF(OR(E41=0,H41<0),"KRITISK",IF(H41<0.2,"HØJ",IF(H41<0.35,"MIDDEL","OK")))) -> HØJ | J41: =IF(G41="","",MAX(E41,CEILING(G41/(1-Forudsætninger!$B$4)*(1+Forudsætninger!$B$3),IF(G41/(1-Forudsætninger!$B$4)*(1+Forudsætninger!$B$3)<50,1,IF(G41/(1-Forudsætninger!$B$4)*(1+Forudsætninger!$B$3)<200,5,10))))) -> 75 | K41: =IF(OR(J41="",E41=0),"",J41/E41-1) -> 0.70454545 | L41: =IF(J41="","",(J41/(1+Forudsætninger!$B$3)-G41)/(J41/(1+Forudsætninger!$B$3))) -> 0.46833333 | M41: Kork slibeklods 70x93mm 10 stk/pk. | N41: Leverandørpris 31,90 er muligvis pr. 10-pak (uklart på listen) – tjek.
A42: Rullehåndtag | B42: Håndtag 15-25 cm | Håndtag | C42: 18 cm | D42: 1864-366 | E42: 41 | F42: =E42/(1+Forudsætninger!$B$3) -> 32.8 | G42: 29.7 | H42: =IF(OR(G42="",F42=0),"",(F42-G42)/F42) -> 0.094512195 | I42: =IF(G42="","UKENDT",IF(OR(E42=0,H42<0),"KRITISK",IF(H42<0.2,"HØJ",IF(H42<0.35,"MIDDEL","OK")))) -> HØJ | J42: =IF(G42="","",MAX(E42,CEILING(G42/(1-Forudsætninger!$B$4)*(1+Forudsætninger!$B$3),IF(G42/(1-Forudsætninger!$B$4)*(1+Forudsætninger!$B$3)<50,1,IF(G42/(1-Forudsætninger!$B$4)*(1+Forudsætninger!$B$3)<200,5,10))))) -> 70 | K42: =IF(OR(J42="",E42=0),"",J42/E42-1) -> 0.70731707 | L42: =IF(J42="","",(J42/(1+Forudsætninger!$B$3)-G42)/(J42/(1+Forudsætninger!$B$3))) -> 0.46964286 | M42: Pronelli Håndtag 18cm.
A43: Rullehåndtag | B43: Håndtag 10 cm | Håndtag | C43: 10 cm | D43: 1061-366 | E43: 35 | F43: =E43/(1+Forudsætninger!$B$3) -> 28 | G43: 25.3 | H43: =IF(OR(G43="",F43=0),"",(F43-G43)/F43) -> 0.096428571 | I43: =IF(G43="","UKENDT",IF(OR(E43=0,H43<0),"KRITISK",IF(H43<0.2,"HØJ",IF(H43<0.35,"MIDDEL","OK")))) -> HØJ | J43: =IF(G43="","",MAX(E43,CEILING(G43/(1-Forudsætninger!$B$4)*(1+Forudsætninger!$B$3),IF(G43/(1-Forudsætninger!$B$4)*(1+Forudsætninger!$B$3)<50,1,IF(G43/(1-Forudsætninger!$B$4)*(1+Forudsætninger!$B$3)<200,5,10))))) -> 60 | K43: =IF(OR(J43="",E43=0),"",J43/E43-1) -> 0.71428571 | L43: =IF(J43="","",(J43/(1+Forudsætninger!$B$3)-G43)/(J43/(1+Forudsætninger!$B$3))) -> 0.47291667 | M43: Pronelli Håndtag 10cm. B.115gr-N.106gr.
A44: Pensler | B44: Fladpensel | Gemini | C44: 50mm | D44: 52-TINGO/50F1 | E44: 70 | F44: =E44/(1+Forudsætninger!$B$3) -> 56 | G44: 50.49 | H44: =IF(OR(G44="",F44=0),"",(F44-G44)/F44) -> 0.098392857 | I44: =IF(G44="","UKENDT",IF(OR(E44=0,H44<0),"KRITISK",IF(H44<0.2,"HØJ",IF(H44<0.35,"MIDDEL","OK")))) -> HØJ | J44: =IF(G44="","",MAX(E44,CEILING(G44/(1-Forudsætninger!$B$4)*(1+Forudsætninger!$B$3),IF(G44/(1-Forudsætninger!$B$4)*(1+Forudsætninger!$B$3)<50,1,IF(G44/(1-Forudsætninger!$B$4)*(1+Forudsætninger!$B$3)<200,5,10))))) -> 115 | K44: =IF(OR(J44="",E44=0),"",J44/E44-1) -> 0.64285714 | L44: =IF(J44="","",(J44/(1+Forudsætninger!$B$3)-G44)/(J44/(1+Forudsætninger!$B$3))) -> 0.45119565 | M44: Pronelli Gemini. Fladpensel 50mm
A45: Pensler | B45: Fladpensel | Gemini | C45: 30mm | D45: 52-TINGO/30F1 | E45: 42 | F45: =E45/(1+Forudsætninger!$B$3) -> 33.6 | G45: 30.294 | H45: =IF(OR(G45="",F45=0),"",(F45-G45)/F45) -> 0.098392857 | I45: =IF(G45="","UKENDT",IF(OR(E45=0,H45<0),"KRITISK",IF(H45<0.2,"HØJ",IF(H45<0.35,"MIDDEL","OK")))) -> HØJ | J45: =IF(G45="","",MAX(E45,CEILING(G45/(1-Forudsætninger!$B$4)*(1+Forudsætninger!$B$3),IF(G45/(1-Forudsætninger!$B$4)*(1+Forudsætninger!$B$3)<50,1,IF(G45/(1-Forudsætninger!$B$4)*(1+Forudsætninger!$B$3)<200,5,10))))) -> 70 | K45: =IF(OR(J45="",E45=0),"",J45/E45-1) -> 0.66666667 | L45: =IF(J45="","",(J45/(1+Forudsætninger!$B$3)-G45)/(J45/(1+Forudsætninger!$B$3))) -> 0.45903571 | M45: Pronelli Gemini. Fladpensel 30mm
A46: Diverse | B46: Penselsæt | C46: – | D46: 100002SB | E46: 29 | F46: =E46/(1+Forudsætninger!$B$3) -> 23.2 | G46: 20.9 | H46: =IF(OR(G46="",F46=0),"",(F46-G46)/F46) -> 0.099137931 | I46: =IF(G46="","UKENDT",IF(OR(E46=0,H46<0),"KRITISK",IF(H46<0.2,"HØJ",IF(H46<0.35,"MIDDEL","OK")))) -> HØJ | J46: =IF(G46="","",MAX(E46,CEILING(G46/(1-Forudsætninger!$B$4)*(1+Forudsætninger!$B$3),IF(G46/(1-Forudsætninger!$B$4)*(1+Forudsætninger!$B$3)<50,1,IF(G46/(1-Forudsætninger!$B$4)*(1+Forudsætninger!$B$3)<200,5,10))))) -> 48 | K46: =IF(OR(J46="",E46=0),"",J46/E46-1) -> 0.65517241 | L46: =IF(J46="","",(J46/(1+Forudsætninger!$B$3)-G46)/(J46/(1+Forudsætninger!$B$3))) -> 0.45572917 | M46: Penselsæt Fine børster. no 4-10
A47: Ruller | B47: Blue Tex | Ruller | C47: 10 cm | D47: 973410-10 | E47: 22 | F47: =E47/(1+Forudsætninger!$B$3) -> 17.6 | G47: 15.774 | H47: =IF(OR(G47="",F47=0),"",(F47-G47)/F47) -> 0.10375 | I47: =IF(G47="","UKENDT",IF(OR(E47=0,H47<0),"KRITISK",IF(H47<0.2,"HØJ",IF(H47<0.35,"MIDDEL","OK")))) -> HØJ | J47: =IF(G47="","",MAX(E47,CEILING(G47/(1-Forudsætninger!$B$4)*(1+Forudsætninger!$B$3),IF(G47/(1-Forudsætninger!$B$4)*(1+Forudsætninger!$B$3)<50,1,IF(G47/(1-Forudsætninger!$B$4)*(1+Forudsætninger!$B$3)<200,5,10))))) -> 36 | K47: =IF(OR(J47="",E47=0),"",J47/E47-1) -> 0.63636364 | L47: =IF(J47="","",(J47/(1+Forudsætninger!$B$3)-G47)/(J47/(1+Forudsætninger!$B$3))) -> 0.45229167 | M47: Microfiber Blue-tex 10cm/Ø15mm/luv16mm 10 stk pk. | N47: Leverandørpris 15,77 er muligvis pr. 10-pak (uklart på listen) – tjek.
A48: Spartler | B48: Japan spartelsæt | C48: 50-120 mm | D48: 812004SB | E48: 60 | F48: =E48/(1+Forudsætninger!$B$3) -> 48 | G48: 42.9 | H48: =IF(OR(G48="",F48=0),"",(F48-G48)/F48) -> 0.10625 | I48: =IF(G48="","UKENDT",IF(OR(E48=0,H48<0),"KRITISK",IF(H48<0.2,"HØJ",IF(H48<0.35,"MIDDEL","OK")))) -> HØJ | J48: =IF(G48="","",MAX(E48,CEILING(G48/(1-Forudsætninger!$B$4)*(1+Forudsætninger!$B$3),IF(G48/(1-Forudsætninger!$B$4)*(1+Forudsætninger!$B$3)<50,1,IF(G48/(1-Forudsætninger!$B$4)*(1+Forudsætninger!$B$3)<200,5,10))))) -> 100 | K48: =IF(OR(J48="",E48=0),"",J48/E48-1) -> 0.66666667 | L48: =IF(J48="","",(J48/(1+Forudsætninger!$B$3)-G48)/(J48/(1+Forudsætninger!$B$3))) -> 0.46375 | M48: Japanspartel sæt.
A49: Diverse | B49: Rullebakkesæt inkl. pensel | C49: – | D49: SET724400-05 | E49: 71 | F49: =E49/(1+Forudsætninger!$B$3) -> 56.8 | G49: 50.6 | H49: =IF(OR(G49="",F49=0),"",(F49-G49)/F49) -> 0.10915493 | I49: =IF(G49="","UKENDT",IF(OR(E49=0,H49<0),"KRITISK",IF(H49<0.2,"HØJ",IF(H49<0.35,"MIDDEL","OK")))) -> HØJ | J49: =IF(G49="","",MAX(E49,CEILING(G49/(1-Forudsætninger!$B$4)*(1+Forudsætninger!$B$3),IF(G49/(1-Forudsætninger!$B$4)*(1+Forudsætninger!$B$3)<50,1,IF(G49/(1-Forudsætninger!$B$4)*(1+Forudsætninger!$B$3)<200,5,10))))) -> 115 | K49: =IF(OR(J49="",E49=0),"",J49/E49-1) -> 0.61971831 | L49: =IF(J49="","",(J49/(1+Forudsætninger!$B$3)-G49)/(J49/(1+Forudsætninger!$B$3))) -> 0.45 | M49: Rullebakkesæt bestående af 5 dele. Rulle / pensler mv.
A50: Pensler | B50: Jumbopensel ECO | C50: 50mm | D50: 52-292ECO/50F1 | E50: 90 | F50: =E50/(1+Forudsætninger!$B$3) -> 72 | G50: 63.8 | H50: =IF(OR(G50="",F50=0),"",(F50-G50)/F50) -> 0.11388889 | I50: =IF(G50="","UKENDT",IF(OR(E50=0,H50<0),"KRITISK",IF(H50<0.2,"HØJ",IF(H50<0.35,"MIDDEL","OK")))) -> HØJ | J50: =IF(G50="","",MAX(E50,CEILING(G50/(1-Forudsætninger!$B$4)*(1+Forudsætninger!$B$3),IF(G50/(1-Forudsætninger!$B$4)*(1+Forudsætninger!$B$3)<50,1,IF(G50/(1-Forudsætninger!$B$4)*(1+Forudsætninger!$B$3)<200,5,10))))) -> 145 | K50: =IF(OR(J50="",E50=0),"",J50/E50-1) -> 0.61111111 | L50: =IF(J50="","",(J50/(1+Forudsætninger!$B$3)-G50)/(J50/(1+Forudsætninger!$B$3))) -> 0.45 | M50: ProNelli Jumbo 50 ECO
A51: Tape | B51: Projekt Washi UV tape | Tape | C51: 36 mm | D51: 508-36 | E51: 75 | F51: =E51/(1+Forudsætninger!$B$3) -> 60 | G51: 52.8 | H51: =IF(OR(G51="",F51=0),"",(F51-G51)/F51) -> 0.12 | I51: =IF(G51="","UKENDT",IF(OR(E51=0,H51<0),"KRITISK",IF(H51<0.2,"HØJ",IF(H51<0.35,"MIDDEL","OK")))) -> HØJ | J51: =IF(G51="","",MAX(E51,CEILING(G51/(1-Forudsætninger!$B$4)*(1+Forudsætninger!$B$3),IF(G51/(1-Forudsætninger!$B$4)*(1+Forudsætninger!$B$3)<50,1,IF(G51/(1-Forudsætninger!$B$4)*(1+Forudsætninger!$B$3)<200,5,10))))) -> 120 | K51: =IF(OR(J51="",E51=0),"",J51/E51-1) -> 0.6 | L51: =IF(J51="","",(J51/(1+Forudsætninger!$B$3)-G51)/(J51/(1+Forudsætninger!$B$3))) -> 0.45 | M51: Projekt Washi UV TAPE. 36MMX50M 24STK/KOLLI.
A52: Rullehåndtag | B52: Håndtag 15-25 cm | Håndtag | C52: 15 cm | D52: 972915 | E52: 50 | F52: =E52/(1+Forudsætninger!$B$3) -> 40 | G52: 34.65 | H52: =IF(OR(G52="",F52=0),"",(F52-G52)/F52) -> 0.13375 | I52: =IF(G52="","UKENDT",IF(OR(E52=0,H52<0),"KRITISK",IF(H52<0.2,"HØJ",IF(H52<0.35,"MIDDEL","OK")))) -> HØJ | J52: =IF(G52="","",MAX(E52,CEILING(G52/(1-Forudsætninger!$B$4)*(1+Forudsætninger!$B$3),IF(G52/(1-Forudsætninger!$B$4)*(1+Forudsætninger!$B$3)<50,1,IF(G52/(1-Forudsætninger!$B$4)*(1+Forudsætninger!$B$3)<200,5,10))))) -> 80 | K52: =IF(OR(J52="",E52=0),"",J52/E52-1) -> 0.6 | L52: =IF(J52="","",(J52/(1+Forudsætninger!$B$3)-G52)/(J52/(1+Forudsætninger!$B$3))) -> 0.45859375 | M52: Håndtag Sort Grib 15 cm. MK
A53: Tape | B53: Masking tape standard | Tape | C53: 24 mm | D53: 3804-24 | E53: 27 | F53: =E53/(1+Forudsætninger!$B$3) -> 21.6 | G53: 18.7 | H53: =IF(OR(G53="",F53=0),"",(F53-G53)/F53) -> 0.13425926 | I53: =IF(G53="","UKENDT",IF(OR(E53=0,H53<0),"KRITISK",IF(H53<0.2,"HØJ",IF(H53<0.35,"MIDDEL","OK")))) -> HØJ | J53: =IF(G53="","",MAX(E53,CEILING(G53/(1-Forudsætninger!$B$4)*(1+Forudsætninger!$B$3),IF(G53/(1-Forudsætninger!$B$4)*(1+Forudsætninger!$B$3)<50,1,IF(G53/(1-Forudsætninger!$B$4)*(1+Forudsætninger!$B$3)<200,5,10))))) -> 43 | K53: =IF(OR(J53="",E53=0),"",J53/E53-1) -> 0.59259259 | L53: =IF(J53="","",(J53/(1+Forudsætninger!$B$3)-G53)/(J53/(1+Forudsætninger!$B$3))) -> 0.45639535 | M53: MASKING TAPE STANDARD 24X50MM. 36 STK/KOLLI
A54: Ruller | B54: Skumvalse | Ruller | C54: 5 cm | D54: 745206-02 | E54: 32 | F54: =E54/(1+Forudsætninger!$B$3) -> 25.6 | G54: 21.956 | H54: =IF(OR(G54="",F54=0),"",(F54-G54)/F54) -> 0.14234375 | I54: =IF(G54="","UKENDT",IF(OR(E54=0,H54<0),"KRITISK",IF(H54<0.2,"HØJ",IF(H54<0.35,"MIDDEL","OK")))) -> HØJ | J54: =IF(G54="","",MAX(E54,CEILING(G54/(1-Forudsætninger!$B$4)*(1+Forudsætninger!$B$3),IF(G54/(1-Forudsætninger!$B$4)*(1+Forudsætninger!$B$3)<50,1,IF(G54/(1-Forudsætninger!$B$4)*(1+Forudsætninger!$B$3)<200,5,10))))) -> 50 | K54: =IF(OR(J54="",E54=0),"",J54/E54-1) -> 0.5625 | L54: =IF(J54="","",(J54/(1+Forudsætninger!$B$3)-G54)/(J54/(1+Forudsætninger!$B$3))) -> 0.4511 | M54: Skumrulle 5cm, (2stk-pk.) MK
A55: Tape | B55: Washi Tape Premium | Tape | C55: 36 mm | D55: 3808-36 | E55: 90 | F55: =E55/(1+Forudsætninger!$B$3) -> 72 | G55: 61.6 | H55: =IF(OR(G55="",F55=0),"",(F55-G55)/F55) -> 0.14444444 | I55: =IF(G55="","UKENDT",IF(OR(E55=0,H55<0),"KRITISK",IF(H55<0.2,"HØJ",IF(H55<0.35,"MIDDEL","OK")))) -> HØJ | J55: =IF(G55="","",MAX(E55,CEILING(G55/(1-Forudsætninger!$B$4)*(1+Forudsætninger!$B$3),IF(G55/(1-Forudsætninger!$B$4)*(1+Forudsætninger!$B$3)<50,1,IF(G55/(1-Forudsætninger!$B$4)*(1+Forudsætninger!$B$3)<200,5,10))))) -> 140 | K55: =IF(OR(J55="",E55=0),"",J55/E55-1) -> 0.55555556 | L55: =IF(J55="","",(J55/(1+Forudsætninger!$B$3)-G55)/(J55/(1+Forudsætninger!$B$3))) -> 0.45 | M55: WASHI TAPE PREMIUM 36X50MM 24STK/KOLLI.
A56: Diverse | B56: Penselsæt | C56: 40-100 mm | D56: 52-9160 | E56: 126 | F56: =E56/(1+Forudsætninger!$B$3) -> 100.8 | G56: 85.8 | H56: =IF(OR(G56="",F56=0),"",(F56-G56)/F56) -> 0.14880952 | I56: =IF(G56="","UKENDT",IF(OR(E56=0,H56<0),"KRITISK",IF(H56<0.2,"HØJ",IF(H56<0.35,"MIDDEL","OK")))) -> HØJ | J56: =IF(G56="","",MAX(E56,CEILING(G56/(1-Forudsætninger!$B$4)*(1+Forudsætninger!$B$3),IF(G56/(1-Forudsætninger!$B$4)*(1+Forudsætninger!$B$3)<50,1,IF(G56/(1-Forudsætninger!$B$4)*(1+Forudsætninger!$B$3)<200,5,10))))) -> 195 | K56: =IF(OR(J56="",E56=0),"",J56/E56-1) -> 0.54761905 | L56: =IF(J56="","",(J56/(1+Forudsætninger!$B$3)-G56)/(J56/(1+Forudsætninger!$B$3))) -> 0.45 | M56: Pronelli Penselsæt. 100-50-40 mm. Blåt håndtag med grå børster.
A57: Tape | B57: Ultra Sharp Red | Tape | C57: 36 mm | D57: 3301-36 | E57: 180 | F57: =E57/(1+Forudsætninger!$B$3) -> 144 | G57: 121 | H57: =IF(OR(G57="",F57=0),"",(F57-G57)/F57) -> 0.15972222 | I57: =IF(G57="","UKENDT",IF(OR(E57=0,H57<0),"KRITISK",IF(H57<0.2,"HØJ",IF(H57<0.35,"MIDDEL","OK")))) -> HØJ | J57: =IF(G57="","",MAX(E57,CEILING(G57/(1-Forudsætninger!$B$4)*(1+Forudsætninger!$B$3),IF(G57/(1-Forudsætninger!$B$4)*(1+Forudsætninger!$B$3)<50,1,IF(G57/(1-Forudsætninger!$B$4)*(1+Forudsætninger!$B$3)<200,5,10))))) -> 280 | K57: =IF(OR(J57="",E57=0),"",J57/E57-1) -> 0.55555556 | L57: =IF(J57="","",(J57/(1+Forudsætninger!$B$3)-G57)/(J57/(1+Forudsætninger!$B$3))) -> 0.45982143 | M57: ULTRA SHARP RED 36X50MM 24STK/KOLLI.
A58: Diverse | B58: Forlængerskaft | C58: 60cm | D58: 765562 | E58: 46 | F58: =E58/(1+Forudsætninger!$B$3) -> 36.8 | G58: 30.8 | H58: =IF(OR(G58="",F58=0),"",(F58-G58)/F58) -> 0.16304348 | I58: =IF(G58="","UKENDT",IF(OR(E58=0,H58<0),"KRITISK",IF(H58<0.2,"HØJ",IF(H58<0.35,"MIDDEL","OK")))) -> HØJ | J58: =IF(G58="","",MAX(E58,CEILING(G58/(1-Forudsætninger!$B$4)*(1+Forudsætninger!$B$3),IF(G58/(1-Forudsætninger!$B$4)*(1+Forudsætninger!$B$3)<50,1,IF(G58/(1-Forudsætninger!$B$4)*(1+Forudsætninger!$B$3)<200,5,10))))) -> 70 | K58: =IF(OR(J58="",E58=0),"",J58/E58-1) -> 0.52173913 | L58: =IF(J58="","",(J58/(1+Forudsætninger!$B$3)-G58)/(J58/(1+Forudsætninger!$B$3))) -> 0.45 | M58: Teleskop 60cm. 6 stk/pk. MK
A59: Sandpapir | B59: Sandpapir D421, 5 m | Slibepapir | C59: Korn 40 | D59: 15420 | E59: 99 | F59: =E59/(1+Forudsætninger!$B$3) -> 79.2 | G59: 66 | H59: =IF(OR(G59="",F59=0),"",(F59-G59)/F59) -> 0.16666667 | I59: =IF(G59="","UKENDT",IF(OR(E59=0,H59<0),"KRITISK",IF(H59<0.2,"HØJ",IF(H59<0.35,"MIDDEL","OK")))) -> HØJ | J59: =IF(G59="","",MAX(E59,CEILING(G59/(1-Forudsætninger!$B$4)*(1+Forudsætninger!$B$3),IF(G59/(1-Forudsætninger!$B$4)*(1+Forudsætninger!$B$3)<50,1,IF(G59/(1-Forudsætninger!$B$4)*(1+Forudsætninger!$B$3)<200,5,10))))) -> 150 | K59: =IF(OR(J59="",E59=0),"",J59/E59-1) -> 0.51515152 | L59: =IF(J59="","",(J59/(1+Forudsætninger!$B$3)-G59)/(J59/(1+Forudsætninger!$B$3))) -> 0.45 | M59: Sandpapir Korn 40. 100mm x 5m rulle. 421
... A187: Pensler | B187: Radiatorpensel | Syntetisk | C187: 50mm | D187: 52-22/50 | E187: 90 | F187: =E187/(1+Forudsætninger!$B$3) -> 72 | G187: 42.9 | H187: =IF(OR(G187="",F187=0),"",(F187-G187)/F187) -> 0.40416667 | I187: =IF(G187="","UKENDT",IF(OR(E187=0,H187<0),"KRITISK",IF(H187<0.2,"HØJ",IF(H187<0.35,"MIDDEL","OK")))) -> OK | J187: =IF(G187="","",MAX(E187,CEILING(G187/(1-Forudsætninger!$B$4)*(1+Forudsætninger!$B$3),IF(G187/(1-Forudsætninger!$B$4)*(1+Forudsætninger!$B$3)<50,1,IF(G187/(1-Forudsætninger!$B$4)*(1+Forudsætninger!$B$3)<200,5,10))))) -> 100 | K187: =IF(OR(J187="",E187=0),"",J187/E187-1) -> 0.11111111 | L187: =IF(J187="","",(J187/(1+Forudsætninger!$B$3)-G187)/(J187/(1+Forudsætninger!$B$3))) -> 0.46375 | M187: Pronelli Radiatorpensel 50mm, Microfiber
A188: Ruller | B188: Blue Tex | Ruller | C188: 12 cm | D188: 973412-10 | E188: 47 | F188: =E188/(1+Forudsætninger!$B$3) -> 37.6 | G188: 22 | H188: =IF(OR(G188="",F188=0),"",(F188-G188)/F188) -> 0.41489362 | I188: =IF(G188="","UKENDT",IF(OR(E188=0,H188<0),"KRITISK",IF(H188<0.2,"HØJ",IF(H188<0.35,"MIDDEL","OK")))) -> OK | J188: =IF(G188="","",MAX(E188,CEILING(G188/(1-Forudsætninger!$B$4)*(1+Forudsætninger!$B$3),IF(G188/(1-Forudsætninger!$B$4)*(1+Forudsætninger!$B$3)<50,1,IF(G188/(1-Forudsætninger!$B$4)*(1+Forudsætninger!$B$3)<200,5,10))))) -> 50 | K188: =IF(OR(J188="",E188=0),"",J188/E188-1) -> 0.063829787 | L188: =IF(J188="","",(J188/(1+Forudsætninger!$B$3)-G188)/(J188/(1+Forudsætninger!$B$3))) -> 0.45 | M188: Microfiber Blue-tex 12cm /Ø30MM / 10 STK. PK. | N188: Leverandørpris 22,00 er muligvis pr. 10-pak (uklart på listen) – tjek.
A189: Ruller | B189: Gamma Twist | Ruller | C189: 25 cm | D189: 52-457/25R | E189: 140 | F189: =E189/(1+Forudsætninger!$B$3) -> 112 | G189: 64.9 | H189: =IF(OR(G189="",F189=0),"",(F189-G189)/F189) -> 0.42053571 | I189: =IF(G189="","UKENDT",IF(OR(E189=0,H189<0),"KRITISK",IF(H189<0.2,"HØJ",IF(H189<0.35,"MIDDEL","OK")))) -> OK | J189: =IF(G189="","",MAX(E189,CEILING(G189/(1-Forudsætninger!$B$4)*(1+Forudsætninger!$B$3),IF(G189/(1-Forudsætninger!$B$4)*(1+Forudsætninger!$B$3)<50,1,IF(G189/(1-Forudsætninger!$B$4)*(1+Forudsætninger!$B$3)<200,5,10))))) -> 150 | K189: =IF(OR(J189="",E189=0),"",J189/E189-1) -> 0.071428571 | L189: =IF(J189="","",(J189/(1+Forudsætninger!$B$3)-G189)/(J189/(1+Forudsætninger!$B$3))) -> 0.45916667 | M189: Gamma Twist rulle/stick. 631077
A190: Pensler | B190: Stickpensel | Gemini | C190: 40mm | D190: 52-293/40F1 | E190: 89 | F190: =E190/(1+Forudsætninger!$B$3) -> 71.2 | G190: 40.48 | H190: =IF(OR(G190="",F190=0),"",(F190-G190)/F190) -> 0.43146067 | I190: =IF(G190="","UKENDT",IF(OR(E190=0,H190<0),"KRITISK",IF(H190<0.2,"HØJ",IF(H190<0.35,"MIDDEL","OK")))) -> OK | J190: =IF(G190="","",MAX(E190,CEILING(G190/(1-Forudsætninger!$B$4)*(1+Forudsætninger!$B$3),IF(G190/(1-Forudsætninger!$B$4)*(1+Forudsætninger!$B$3)<50,1,IF(G190/(1-Forudsætninger!$B$4)*(1+Forudsætninger!$B$3)<200,5,10))))) -> 95 | K190: =IF(OR(J190="",E190=0),"",J190/E190-1) -> 0.06741573 | L190: =IF(J190="","",(J190/(1+Forudsætninger!$B$3)-G190)/(J190/(1+Forudsætninger!$B$3))) -> 0.46736842 | M190: ProNelli Gemini Synt. Stick 40.
A191: Pensler | B191: Stickpensel | Soft | C191: 40mm | D191: 52-314/40F1 | E191: 90 | F191: =E191/(1+Forudsætninger!$B$3) -> 72 | G191: 40.48 | H191: =IF(OR(G191="",F191=0),"",(F191-G191)/F191) -> 0.43777778 | I191: =IF(G191="","UKENDT",IF(OR(E191=0,H191<0),"KRITISK",IF(H191<0.2,"HØJ",IF(H191<0.35,"MIDDEL","OK")))) -> OK | J191: =IF(G191="","",MAX(E191,CEILING(G191/(1-Forudsætninger!$B$4)*(1+Forudsætninger!$B$3),IF(G191/(1-Forudsætninger!$B$4)*(1+Forudsætninger!$B$3)<50,1,IF(G191/(1-Forudsætninger!$B$4)*(1+Forudsætninger!$B$3)<200,5,10))))) -> 95 | K191: =IF(OR(J191="",E191=0),"",J191/E191-1) -> 0.055555556 | L191: =IF(J191="","",(J191/(1+Forudsætninger!$B$3)-G191)/(J191/(1+Forudsætninger!$B$3))) -> 0.46736842 | M191: ProNelli Soft. Synt. Stick 40 mm
A192: Pensler | B192: Stickpensel | Soft | C192: 30mm | D192: 52-314/30F1 | E192: 80 | F192: =E192/(1+Forudsætninger!$B$3) -> 64 | G192: 35.64 | H192: =IF(OR(G192="",F192=0),"",(F192-G192)/F192) -> 0.443125 | I192: =IF(G192="","UKENDT",IF(OR(E192=0,H192<0),"KRITISK",IF(H192<0.2,"HØJ",IF(H192<0.35,"MIDDEL","OK")))) -> OK | J192: =IF(G192="","",MAX(E192,CEILING(G192/(1-Forudsætninger!$B$4)*(1+Forudsætninger!$B$3),IF(G192/(1-Forudsætninger!$B$4)*(1+Forudsætninger!$B$3)<50,1,IF(G192/(1-Forudsætninger!$B$4)*(1+Forudsætninger!$B$3)<200,5,10))))) -> 85 | K192: =IF(OR(J192="",E192=0),"",J192/E192-1) -> 0.0625 | L192: =IF(J192="","",(J192/(1+Forudsætninger!$B$3)-G192)/(J192/(1+Forudsætninger!$B$3))) -> 0.47588235 | M192: ProNelli Soft. Synt. Stick 30 mm
A193: Pensler | B193: Stickpensel | Gemini | C193: 30mm | D193: 52-293/30F1 | E193: 80 | F193: =E193/(1+Forudsætninger!$B$3) -> 64 | G193: 35.64 | H193: =IF(OR(G193="",F193=0),"",(F193-G193)/F193) -> 0.443125 | I193: =IF(G193="","UKENDT",IF(OR(E193=0,H193<0),"KRITISK",IF(H193<0.2,"HØJ",IF(H193<0.35,"MIDDEL","OK")))) -> OK | J193: =IF(G193="","",MAX(E193,CEILING(G193/(1-Forudsætninger!$B$4)*(1+Forudsætninger!$B$3),IF(G193/(1-Forudsætninger!$B$4)*(1+Forudsætninger!$B$3)<50,1,IF(G193/(1-Forudsætninger!$B$4)*(1+Forudsætninger!$B$3)<200,5,10))))) -> 85 | K193: =IF(OR(J193="",E193=0),"",J193/E193-1) -> 0.0625 | L193: =IF(J193="","",(J193/(1+Forudsætninger!$B$3)-G193)/(J193/(1+Forudsætninger!$B$3))) -> 0.47588235 | M193: ProNelli Gemini Synt. Stick 30mm.
...

Sheet Forudsætninger
A1: Forudsætninger
A3: Moms | B3: 0.25
A4: Målavance (af pris ekskl. moms) | B4: 0.45
A5: Kilde, kostpriser | B5: "Lars Frey Farve og Lak ruller og pensler.pdf" (special-pris ekskl. moms) i projektmappen
A6: Kilde, salgspriser | B6: Shopify, 2. september 2026 – inkl. de 65 varianter der blev hævet samme dag (se Note-kolonnen)
A7: Kategori | B7: Produktets kategori-tag i Shopify (samme inddeling som på Produkter-siden)
A9: Blå celler kan ændres. Ændrer du målavancen i B4, opdateres "Foreslået pris" på fanen Prisanalyse.
A11: Prioritet | B11: Regel
A12: KRITISK | B12: Sælges under kostpris (negativ avance) eller pris 0 kr
A13: HØJ | B13: Avance under 20 % – dækker knap nok håndtering og fragt
A14: MIDDEL | B14: Avance 20–35 %
A15: OK | B15: Avance 35 % og derover
A16: UKENDT | B16: Ingen kostpris på leverandørlisten
